Workbook

Sheet README
A1: THE UNLOX ACADEMY - DA/DS TRACK
A2: Excel Minor Project - Sales Operations Analytics
A3: Interview-Grade Data Analytics Assessment · 100 Marks
A5: THE SCENARIO
A6: You have just joined the analytics team at a fast-growing multi-category retailer operating across 6 Indian cities.
A7: The head of sales has handed you 5 raw data files - Orders, Customers, Products, Sales Reps, and Targets - and asked
A8: you to answer a set of business questions before the leadership review tomorrow morning.
A10: The data is REAL-WORLD messy: duplicates, missing references, inconsistent case, invalid records, discontinued SKUs.
A11: Part of the assessment is spotting and handling these issues correctly. A wrong-looking answer isn't always wrong -
A12: sometimes the data itself is telling a story.
A14: RULES OF THE ASSESSMENT
A15: 1. Write your answer in the YELLOW cells on each question sheet. Empty answer cell = 0 marks.
... A22: MARKS DISTRIBUTION
A23: Section | B23: Topic | C23: Questions | D23: Marks
A24: Q1 | B24: Lookup Functions (VLOOKUP, INDEX-MATCH, chained lookups) | C24: 8 | D24: 25
A25: Q2 | B25: Data Cleaning & Quality Diagnostics | C25: 6 | D25: 20
A26: Q3 | B26: Conditional Aggregation (SUMIFS, COUNTIFS, IF logic) | C26: 6 | D26: 25
A27: Q4 | B27: Pivot Tables (2D pivots, % of total, calculated fields) | C27: 5 | D27: 20
A28: Q5 | B28: Advanced (Ranking, Running Totals, Multi-condition) | C28: 5 | D28: 10
B29: TOTAL | C29: 30 | D29: 100
A32: PERFORMANCE TIERS
A33: Marks | B33: Tier | C33: Interview Verdict
A34: 85 - 100 | B34: Excellent | C34: Round 1 clear - Excel not a concern
A35: 70 - 84 | B35: Good | C35: Round 1 clear with minor gaps
A36: 55 - 69 | B36: Borderline | C36: Round 1 uncertain - needs revision
A37: 40 - 54 | B37: Weak | C37: Round 1 likely reject - 2 weeks of practice needed
A38: < 40 | B38: Insufficient | C38: Round 1 reject - foundational gaps
A41: DATA SHEETS OVERVIEW
A42: Sheet | B42: Rows | C42: Key Columns | D42: Joins to
A43: Orders | B43: ~2000 | C43: order_id, order_date, customer_id, product_id, sales_rep_id, quantity, unit_price, discount_pct, final_amount, payment_status, ship_city | D43: All others
A44: Customers | B44: 300 | C44: customer_id (PK), customer_name, age, city, segment, signup_date | D44: Orders via customer_id
A45: Products | B45: 60 | C45: product_id (PK), product_name, category, unit_cost, unit_price, is_active | D45: Orders via product_id
A46: Sales_Reps | B46: 30 | C46: rep_id (PK), rep_name, region, hire_date, team_lead_id | D46: Orders via sales_rep_id, self-join via team_lead_id
A47: Targets | B47: 30 × 12 | C47: rep_id (PK), Jan-24 through Dec-24 monthly target values | D47: Sales_Reps via rep_id

Sheet Sheet1
A3: Sum of final_amount | B3: Column Labels
A4: Row Labels | B4: Apparel | C4: Beauty | D4: Electronics | E4: Grocery | F4: Home | G4: Sports | H4: Grand Total
A5: East | B5: 0.13071897 | C5: 0.1930426 | D5: 0.18449707 | E5: 0.17739104 | F5: 0.17073083 | G5: 0.1436195 | H5: 1
A6: North | B6: 0.1402315 | C6: 0.22281123 | D6: 0.2077183 | E6: 0.16021751 | F6: 0.12414513 | G6: 0.14487632 | H6: 1
A7: South | B7: 0.13474631 | C7: 0.22262229 | D7: 0.18391873 | E7: 0.14575149 | F7: 0.15959004 | G7: 0.15337113 | H7: 1
A8: West | B8: 0.14818799 | C8: 0.20284196 | D8: 0.16949062 | E8: 0.17020964 | F8: 0.16306543 | G8: 0.14620437 | H8: 1
A9: Grand Total | B9: 0.13815372 | C9: 0.21098069 | D9: 0.18713592 | E9: 0.16278662 | F9: 0.15380123 | G9: 0.14714182 | H9: 1

Sheet Sheet2
A1: ship_city | B1: Delhi
A3: Average of profit_margin
A4: 0.51594488

Sheet Orders
A1: order_id | B1: order_date | C1: customer_id | D1: product_id | E1: sales_rep_id | F1: quantity | G1: unit_price | H1: discount_pct | I1: final_amount | J1: payment_status | K1: ship_city | L1: Category | M1: Segment | N1: Age | O1: Region | P1: sales_rep_id | Q1: Total Revenue | R1: Region | S1: Category | T1: Unit Cost | V1: rep_id | W1: Total Revenue | X1: Rank
A2: ORD-00001 | B2: 45549 | C2: CUST-0243 | D2: PROD-014 | E2: R007 | F2: 8 | G2: 3620 | H2: 15.4 | I2: 24500.16 | J2: Completed | K2: Pune | L2: =VLOOKUP(D2,Products!$A$2:$F$61,3,FALSE) -> Apparel | M2: =VLOOKUP(C2,Customers!$A$2:$F$301,5,FALSE) -> SMB | N2: =VLOOKUP(C2,Customers!$A$2:$F$301,3,FALSE) -> 44 | O2: =VLOOKUP(E2,Sales_Reps!$A$2:$E$31,3,FALSE) -> North | P2: R007 | Q2: =SUMIFS($I:$I,$E:$E,P2) -> 855749.68 | R2: =VLOOKUP(E2,Sales_Reps!$A$2:$E$100,3,FALSE) -> North | S2: =L2 -> Apparel | T2: =VLOOKUP(D2,Products!$A$2:$F$68,4,FALSE) -> 2509 | V2: R007 | W2: =SUMIF($P$2:$P$2001,V2,$I$2:$I$2001) -> 855749.68 | X2: =_xlfn.RANK.EQ(W2,$W$2:$W$31,0) -> 19
A3: ORD-00002 | B3: 45340 | C3: CUST-0202 | D3: PROD-020 | E3: R005 | F3: 2 | G3: 820 | H3: 10.8 | I3: 1462.88 | J3: Pending | K3: Chennai | L3: =VLOOKUP(D3,Products!$A$2:$F$61,3,FALSE) -> Apparel | M3: =VLOOKUP(C3,Customers!$A$2:$F$301,5,FALSE) -> Retail | N3: =VLOOKUP(C3,Customers!$A$2:$F$301,3,FALSE) -> 39 | O3: =VLOOKUP(E3,Sales_Reps!$A$2:$E$31,3,FALSE) -> North | P3: R005 | Q3: =SUMIFS($I:$I,$E:$E,P3) -> 782445.33 | R3: =VLOOKUP(E3,Sales_Reps!$A$2:$E$100,3,FALSE) -> North | S3: =L3 -> Apparel | T3: =VLOOKUP(D3,Products!$A$2:$F$68,4,FALSE) -> 391 | V3: R005 | W3: =SUMIF($P$2:$P$2001,V3,$I$2:$I$2001) -> 782445.33 | X3: =_xlfn.RANK.EQ(W3,$W$2:$W$31,0) -> 24
A4: ORD-00003 | B4: 45371 | C4: CUST-0098 | D4: PROD-053 | E4: R014 | F4: 8 | G4: 470 | H4: 3.3 | I4: 3635.92 | J4: Pending | K4: Delhi | L4: =VLOOKUP(D4,Products!$A$2:$F$61,3,FALSE) -> Sports | M4: =VLOOKUP(C4,Customers!$A$2:$F$301,5,FALSE) -> Retail | N4: =VLOOKUP(C4,Customers!$A$2:$F$301,3,FALSE) -> 52 | O4: =VLOOKUP(E4,Sales_Reps!$A$2:$E$31,3,FALSE) -> South | P4: R014 | Q4: =SUMIFS($I:$I,$E:$E,P4) -> 995713.54 | R4: =VLOOKUP(E4,Sales_Reps!$A$2:$E$100,3,FALSE) -> South | S4: =L4 -> Sports | T4: =VLOOKUP(D4,Products!$A$2:$F$68,4,FALSE) -> 302 | V4: R014 | W4: =SUMIF($P$2:$P$2001,V4,$I$2:$I$2001) -> 995713.54 | X4: =_xlfn.RANK.EQ(W4,$W$2:$W$31,0) -> 6
A5: ORD-00004 | B5: 45413 | C5: CUST-0071 | D5: PROD-028 | E5: R006 | F5: 1 | G5: 3660 | H5: 15.7 | I5: 3085.38 | J5: Completed | K5: Delhi | L5: =VLOOKUP(D5,Products!$A$2:$F$61,3,FALSE) -> Grocery | M5: =VLOOKUP(C5,Customers!$A$2:$F$301,5,FALSE) -> Corporate | N5: =VLOOKUP(C5,Customers!$A$2:$F$301,3,FALSE) -> 46 | O5: =VLOOKUP(E5,Sales_Reps!$A$2:$E$31,3,FALSE) -> North | P5: R006 | Q5: =SUMIFS($I:$I,$E:$E,P5) -> 1138648.7 | R5: =VLOOKUP(E5,Sales_Reps!$A$2:$E$100,3,FALSE) -> North | S5: =L5 -> Grocery | T5: =VLOOKUP(D5,Products!$A$2:$F$68,4,FALSE) -> 2214 | V5: R006 | W5: =SUMIF($P$2:$P$2001,V5,$I$2:$I$2001) -> 1138648.7 | X5: =_xlfn.RANK.EQ(W5,$W$2:$W$31,0) -> 1
A6: ORD-00005 | B6: 45611 | C6: CUST-0180 | D6: PROD-012 | E6: R008 | F6: 1 | G6: 3160 | H6: 26 | I6: 2338.4 | J6: Completed | K6: Chennai | L6: =VLOOKUP(D6,Products!$A$2:$F$61,3,FALSE) -> Apparel | M6: =VLOOKUP(C6,Customers!$A$2:$F$301,5,FALSE) -> Retail | N6: =VLOOKUP(C6,Customers!$A$2:$F$301,3,FALSE) -> 36 | O6: =VLOOKUP(E6,Sales_Reps!$A$2:$E$31,3,FALSE) -> North | P6: R008 | Q6: =SUMIFS($I:$I,$E:$E,P6) -> 861553.33 | R6: =VLOOKUP(E6,Sales_Reps!$A$2:$E$100,3,FALSE) -> North | S6: =L6 -> Apparel | T6: =VLOOKUP(D6,Products!$A$2:$F$68,4,FALSE) -> 1886 | V6: R008 | W6: =SUMIF($P$2:$P$2001,V6,$I$2:$I$2001) -> 861553.33 | X6: =_xlfn.RANK.EQ(W6,$W$2:$W$31,0) -> 18
A7: ORD-00006 | B7: 45406 | C7: CUST-0275 | D7: PROD-032 | E7: R025 | F7: 4 | G7: 370 | H7: 29 | I7: 1050.8 | J7: Completed | K7: Mumbai | L7: =VLOOKUP(D7,Products!$A$2:$F$61,3,FALSE) -> Home | M7: =VLOOKUP(C7,Customers!$A$2:$F$301,5,FALSE) -> Retail | N7: =VLOOKUP(C7,Customers!$A$2:$F$301,3,FALSE) -> 36 | O7: =VLOOKUP(E7,Sales_Reps!$A$2:$E$31,3,FALSE) -> West | P7: R025 | Q7: =SUMIFS($I:$I,$E:$E,P7) -> 901298.89 | R7: =VLOOKUP(E7,Sales_Reps!$A$2:$E$100,3,FALSE) -> West | S7: =L7 -> Home | T7: =VLOOKUP(D7,Products!$A$2:$F$68,4,FALSE) -> 288 | V7: R025 | W7: =SUMIF($P$2:$P$2001,V7,$I$2:$I$2001) -> 901298.89 | X7: =_xlfn.RANK.EQ(W7,$W$2:$W$31,0) -> 15
A8: ORD-00007 | B8: 45455 | C8: CUST-0293 | D8: PROD-057 | E8: R024 | F8: 3 | G8: 960 | H8: 5.8 | I8: 2712.96 | J8: Completed | K8: Bengaluru | L8: =VLOOKUP(D8,Products!$A$2:$F$61,3,FALSE) -> Sports | M8: =VLOOKUP(C8,Customers!$A$2:$F$301,5,FALSE) -> Retail | N8: =VLOOKUP(C8,Customers!$A$2:$F$301,3,FALSE) -> 27 | O8: =VLOOKUP(E8,Sales_Reps!$A$2:$E$31,3,FALSE) -> West | P8: R024 | Q8: =SUMIFS($I:$I,$E:$E,P8) -> 819558.58 | R8: =VLOOKUP(E8,Sales_Reps!$A$2:$E$100,3,FALSE) -> West | S8: =L8 -> Sports | T8: =VLOOKUP(D8,Products!$A$2:$F$68,4,FALSE) -> 705 | V8: R024 | W8: =SUMIF($P$2:$P$2001,V8,$I$2:$I$2001) -> 819558.58 | X8: =_xlfn.RANK.EQ(W8,$W$2:$W$31,0) -> 20
A9: ORD-00008 | B9: 45617 | C9: CUST-0281 | D9: PROD-007 | E9: R019 | F9: 8 | G9: 1430 | H9: 2.4 | I9: 11165.44 | J9: Completed | K9: Bengaluru | L9: =VLOOKUP(D9,Products!$A$2:$F$61,3,FALSE) -> Electronics | M9: =VLOOKUP(C9,Customers!$A$2:$F$301,5,FALSE) -> Corporate | N9: =VLOOKUP(C9,Customers!$A$2:$F$301,3,FALSE) -> 57 | O9: =VLOOKUP(E9,Sales_Reps!$A$2:$E$31,3,FALSE) -> East | P9: R019 | Q9: =SUMIFS($I:$I,$E:$E,P9) -> 971183.52 | R9: =VLOOKUP(E9,Sales_Reps!$A$2:$E$100,3,FALSE) -> East | S9: =L9 -> Electronics | T9: =VLOOKUP(D9,Products!$A$2:$F$68,4,FALSE) -> 861 | V9: R019 | W9: =SUMIF($P$2:$P$2001,V9,$I$2:$I$2001) -> 971183.52 | X9: =_xlfn.RANK.EQ(W9,$W$2:$W$31,0) -> 10
A10: ORD-00009 | B10: 45549 | C10: CUST-0260 | D10: PROD-038 | E10: R008 | F10: 3 | G10: 5490 | H10: 14.2 | I10: 14131.26 | J10: Completed | K10: Bengaluru | L10: =VLOOKUP(D10,Products!$A$2:$F$61,3,FALSE) -> Home | M10: =VLOOKUP(C10,Customers!$A$2:$F$301,5,FALSE) -> Retail | N10: =VLOOKUP(C10,Customers!$A$2:$F$301,3,FALSE) -> 42 | O10: =VLOOKUP(E10,Sales_Reps!$A$2:$E$31,3,FALSE) -> North | P10: R008 | Q10: =SUMIFS($I:$I,$E:$E,P10) -> 861553.33 | R10: =VLOOKUP(E10,Sales_Reps!$A$2:$E$100,3,FALSE) -> North | S10: =L10 -> Home | T10: =VLOOKUP(D10,Products!$A$2:$F$68,4,FALSE) -> 2549 | V10: R028 | W10: =SUMIF($P$2:$P$2001,V10,$I$2:$I$2001) -> 880468.05 | X10: =_xlfn.RANK.EQ(W10,$W$2:$W$31,0) -> 16
A11: ORD-00010 | B11: 45396 | C11: CUST-0147 | D11: PROD-030 | E11: R028 | F11: 3 | G11: 970 | H11: 1.2 | I11: 2875.08 | J11: Completed | K11: Pune | L11: =VLOOKUP(D11,Products!$A$2:$F$61,3,FALSE) -> Grocery | M11: =VLOOKUP(C11,Customers!$A$2:$F$301,5,FALSE) -> Retail | N11: =VLOOKUP(C11,Customers!$A$2:$F$301,3,FALSE) -> 56 | O11: =VLOOKUP(E11,Sales_Reps!$A$2:$E$31,3,FALSE) -> West | P11: R028 | Q11: =SUMIFS($I:$I,$E:$E,P11) -> 880468.05 | R11: =VLOOKUP(E11,Sales_Reps!$A$2:$E$100,3,FALSE) -> West | S11: =L11 -> Grocery | T11: =VLOOKUP(D11,Products!$A$2:$F$68,4,FALSE) -> 434 | V11: R010 | W11: =SUMIF($P$2:$P$2001,V11,$I$2:$I$2001) -> 880345.2 | X11: =_xlfn.RANK.EQ(W11,$W$2:$W$31,0) -> 17
A12: ORD-00011 | B12: 45560 | C12: CUST-0204 | D12: PROD-024 | E12: R010 | F12: 7 | G12: 2270 | H12: 7.1 | I12: 14761.81 | J12: Pending | K12: Hyderabad | L12: =VLOOKUP(D12,Products!$A$2:$F$61,3,FALSE) -> Grocery | M12: =VLOOKUP(C12,Customers!$A$2:$F$301,5,FALSE) -> Retail | N12: =VLOOKUP(C12,Customers!$A$2:$F$301,3,FALSE) -> 60 | O12: =VLOOKUP(E12,Sales_Reps!$A$2:$E$31,3,FALSE) -> South | P12: R010 | Q12: =SUMIFS($I:$I,$E:$E,P12) -> 880345.2 | R12: =VLOOKUP(E12,Sales_Reps!$A$2:$E$100,3,FALSE) -> South | S12: =L12 -> Grocery | T12: =VLOOKUP(D12,Products!$A$2:$F$68,4,FALSE) -> 1203 | V12: R004 | W12: =SUMIF($P$2:$P$2001,V12,$I$2:$I$2001) -> 589026.29 | X12: =_xlfn.RANK.EQ(W12,$W$2:$W$31,0) -> 29
A13: ORD-00012 | B13: 45332 | C13: CUST-0147 | D13: PROD-010 | E13: R024 | F13: 9 | G13: 2640 | H13: 21.7 | I13: 18604.08 | J13: Completed | K13: Pune | L13: =VLOOKUP(D13,Products!$A$2:$F$61,3,FALSE) -> Electronics | M13: =VLOOKUP(C13,Customers!$A$2:$F$301,5,FALSE) -> Retail | N13: =VLOOKUP(C13,Customers!$A$2:$F$301,3,FALSE) -> 56 | O13: =VLOOKUP(E13,Sales_Reps!$A$2:$E$31,3,FALSE) -> West | P13: R024 | Q13: =SUMIFS($I:$I,$E:$E,P13) -> 819558.58 | R13: =VLOOKUP(E13,Sales_Reps!$A$2:$E$100,3,FALSE) -> West | S13: =L13 -> Electronics | T13: =VLOOKUP(D13,Products!$A$2:$F$68,4,FALSE) -> 1149 | V13: R003 | W13: =SUMIF($P$2:$P$2001,V13,$I$2:$I$2001) -> 986692.91 | X13: =_xlfn.RANK.EQ(W13,$W$2:$W$31,0) -> 7
A14: ORD-00013 | B14: 45507 | C14: CUST-0280 | D14: PROD-002 | E14: R004 | F14: 3 | G14: 2600 | H14: 4.3 | I14: 7464.6 | J14: Cancelled | K14: Delhi | L14: =VLOOKUP(D14,Products!$A$2:$F$61,3,FALSE) -> Electronics | M14: =VLOOKUP(C14,Customers!$A$2:$F$301,5,FALSE) -> SMB | N14: =VLOOKUP(C14,Customers!$A$2:$F$301,3,FALSE) -> 27 | O14: =VLOOKUP(E14,Sales_Reps!$A$2:$E$31,3,FALSE) -> North | P14: R004 | Q14: =SUMIFS($I:$I,$E:$E,P14) -> 589026.29 | R14: =VLOOKUP(E14,Sales_Reps!$A$2:$E$100,3,FALSE) -> North | S14: =L14 -> Electronics | T14: =VLOOKUP(D14,Products!$A$2:$F$68,4,FALSE) -> 1052 | V14: R023 | W14: =SUMIF($P$2:$P$2001,V14,$I$2:$I$2001) -> 983787.48 | X14: =_xlfn.RANK.EQ(W14,$W$2:$W$31,0) -> 8 | AA14: =SUMIFS($I$2:$I$2001,$B$2:$B$2001,"<="&DATE(2024,8,31)) -> 18050690
A15: ORD-00014 | B15: 45466 | C15: CUST-0008 | D15: PROD-036 | E15: R025 | F15: 3 | G15: 3250 | H15: 14.1 | I15: 8375.25 | J15: Refunded | K15: Pune | L15: =VLOOKUP(D15,Products!$A$2:$F$61,3,FALSE) -> Home | M15: =VLOOKUP(C15,Customers!$A$2:$F$301,5,FALSE) -> SMB | N15: =VLOOKUP(C15,Customers!$A$2:$F$301,3,FALSE) -> 39 | O15: =VLOOKUP(E15,Sales_Reps!$A$2:$E$31,3,FALSE) -> West | P15: R025 | Q15: =SUMIFS($I:$I,$E:$E,P15) -> 901298.89 | R15: =VLOOKUP(E15,Sales_Reps!$A$2:$E$100,3,FALSE) -> West | S15: =L15 -> Home | T15: =VLOOKUP(D15,Products!$A$2:$F$68,4,FALSE) -> 1556 | V15: R021 | W15: =SUMIF($P$2:$P$2001,V15,$I$2:$I$2001) -> 761507.17 | X15: =_xlfn.RANK.EQ(W15,$W$2:$W$31,0) -> 26
A16: ORD-00015 | B16: 45365 | C16: CUST-0052 | D16: PROD-060 | E16: R003 | F16: 1 | G16: 190 | H16: 20.7 | I16: 150.67 | J16: Completed | K16: Pune | L16: =VLOOKUP(D16,Products!$A$2:$F$61,3,FALSE) -> Sports | M16: =VLOOKUP(C16,Customers!$A$2:$F$301,5,FALSE) -> Retail | N16: =VLOOKUP(C16,Customers!$A$2:$F$301,3,FALSE) -> 38 | O16: =VLOOKUP(E16,Sales_Reps!$A$2:$E$31,3,FALSE) -> North | P16: R003 | Q16: =SUMIFS($I:$I,$E:$E,P16) -> 986692.91 | R16: =VLOOKUP(E16,Sales_Reps!$A$2:$E$100,3,FALSE) -> North | S16: =L16 -> Sports | T16: =VLOOKUP(D16,Products!$A$2:$F$68,4,FALSE) -> 147 | V16: R030 | W16: =SUMIF($P$2:$P$2001,V16,$I$2:$I$2001) -> 747624.37 | X16: =_xlfn.RANK.EQ(W16,$W$2:$W$31,0) -> 27 | AA16: =SUMIFS($I$2:$I$2001,$B$2:$B$2001,"<="&DATE(2024,8,31)) -> 18050690
A17: ORD-00016 | B17: 45546 | C17: CUST-0184 | D17: PROD-058 | E17: R014 | F17: 7 | G17: 2400 | H17: 10.2 | I17: 15086.4 | J17: Pending | K17: Pune | L17: =VLOOKUP(D17,Products!$A$2:$F$61,3,FALSE) -> Sports | M17: =VLOOKUP(C17,Customers!$A$2:$F$301,5,FALSE) -> Retail | N17: =VLOOKUP(C17,Customers!$A$2:$F$301,3,FALSE) -> 63 | O17: =VLOOKUP(E17,Sales_Reps!$A$2:$E$31,3,FALSE) -> South | P17: R014 | Q17: =SUMIFS($I:$I,$E:$E,P17) -> 995713.54 | R17: =VLOOKUP(E17,Sales_Reps!$A$2:$E$100,3,FALSE) -> South | S17: =L17 -> Sports | T17: =VLOOKUP(D17,Products!$A$2:$F$68,4,FALSE) -> 974 | V17: R015 | W17: =SUMIF($P$2:$P$2001,V17,$I$2:$I$2001) -> 1091740.2 | X17: =_xlfn.RANK.EQ(W17,$W$2:$W$31,0) -> 3
A18: ORD-00017 | B18: 45512 | C18: CUST-0056 | D18: PROD-028 | E18: R023 | F18: 4 | G18: 3660 | H18: 2.6 | I18: 14259.36 | J18: Completed | K18: Bengaluru | L18: =VLOOKUP(D18,Products!$A$2:$F$61,3,FALSE) -> Grocery | M18: =VLOOKUP(C18,Customers!$A$2:$F$301,5,FALSE) -> SMB | N18: =VLOOKUP(C18,Customers!$A$2:$F$301,3,FALSE) -> 46 | O18: =VLOOKUP(E18,Sales_Reps!$A$2:$E$31,3,FALSE) -> East | P18: R023 | Q18: =SUMIFS($I:$I,$E:$E,P18) -> 983787.48 | R18: =VLOOKUP(E18,Sales_Reps!$A$2:$E$100,3,FALSE) -> East | S18: =L18 -> Grocery | T18: =VLOOKUP(D18,Products!$A$2:$F$68,4,FALSE) -> 2214 | V18: R020 | W18: =SUMIF($P$2:$P$2001,V18,$I$2:$I$2001) -> 906107.71 | X18: =_xlfn.RANK.EQ(W18,$W$2:$W$31,0) -> 13
A19: ORD-00018 | B19: 45654 | C19: CUST-0273 | D19: PROD-047 | E19: R021 | F19: 8 | G19: 3450 | H19: 18.5 | I19: 22494 | J19: Completed | K19: Hyderabad | L19: =VLOOKUP(D19,Products!$A$2:$F$61,3,FALSE) -> Beauty | M19: =VLOOKUP(C19,Customers!$A$2:$F$301,5,FALSE) -> Corporate | N19: =VLOOKUP(C19,Customers!$A$2:$F$301,3,FALSE) -> 32 | O19: =VLOOKUP(E19,Sales_Reps!$A$2:$E$31,3,FALSE) -> East | P19: R021 | Q19: =SUMIFS($I:$I,$E:$E,P19) -> 761507.17 | R19: =VLOOKUP(E19,Sales_Reps!$A$2:$E$100,3,FALSE) -> East | S19: =L19 -> Beauty | T19: =VLOOKUP(D19,Products!$A$2:$F$68,4,FALSE) -> 2420 | V19: R026 | W19: =SUMIF($P$2:$P$2001,V19,$I$2:$I$2001) -> 576305.08 | X19: =_xlfn.RANK.EQ(W19,$W$2:$W$31,0) -> 30
A20: ORD-00019 | B20: 45626 | C20: CUST-0182 | D20: PROD-051 | E20: R023 | F20: 5 | G20: 3450 | H20: 7.3 | I20: 15990.75 | J20: Completed | K20: Mumbai | L20: =VLOOKUP(D20,Products!$A$2:$F$61,3,FALSE) -> Sports | M20: =VLOOKUP(C20,Customers!$A$2:$F$301,5,FALSE) -> Retail | N20: =VLOOKUP(C20,Customers!$A$2:$F$301,3,FALSE) -> 54 | O20: =VLOOKUP(E20,Sales_Reps!$A$2:$E$31,3,FALSE) -> East | P20: R023 | Q20: =SUMIFS($I:$I,$E:$E,P20) -> 983787.48 | R20: =VLOOKUP(E20,Sales_Reps!$A$2:$E$100,3,FALSE) -> East | S20: =L20 -> Sports | T20: =VLOOKUP(D20,Products!$A$2:$F$68,4,FALSE) -> 2467 | V20: R009 | W20: =SUMIF($P$2:$P$2001,V20,$I$2:$I$2001) -> 914554.72 | X20: =_xlfn.RANK.EQ(W20,$W$2:$W$31,0) -> 12
A21: ORD-00020 | B21: 45394 | C21: CUST-0265 | D21: PROD-040 | E21: R023 | F21: 8 | G21: 1080 | H21: 2.2 | I21: 8449.92 | J21: Completed | K21: Chennai | L21: =VLOOKUP(D21,Products!$A$2:$F$61,3,FALSE) -> Home | M21: =VLOOKUP(C21,Customers!$A$2:$F$301,5,FALSE) -> Retail | N21: =VLOOKUP(C21,Customers!$A$2:$F$301,3,FALSE) -> 49 | O21: =VLOOKUP(E21,Sales_Reps!$A$2:$E$31,3,FALSE) -> East | P21: R023 | Q21: =SUMIFS($I:$I,$E:$E,P21) -> 983787.48 | R21: =VLOOKUP(E21,Sales_Reps!$A$2:$E$100,3,FALSE) -> East | S21: =L21 -> Home | T21: =VLOOKUP(D21,Products!$A$2:$F$68,4,FALSE) -> 519 | V21: R001 | W21: =SUMIF($P$2:$P$2001,V21,$I$2:$I$2001) -> 789849.6 | X21: =_xlfn.RANK.EQ(W21,$W$2:$W$31,0) -> 23
A22: ORD-00021 | B22: 45470 | C22: CUST-0159 | D22: PROD-019 | E22: R006 | F22: 7 | G22: 2480 | H22: 28.7 | I22: 12377.68 | J22: Completed | K22: Hyderabad | L22: =VLOOKUP(D22,Products!$A$2:$F$61,3,FALSE) -> Apparel | M22: =VLOOKUP(C22,Customers!$A$2:$F$301,5,FALSE) -> Retail | N22: =VLOOKUP(C22,Customers!$A$2:$F$301,3,FALSE) -> 32 | O22: =VLOOKUP(E22,Sales_Reps!$A$2:$E$31,3,FALSE) -> North | P22: R006 | Q22: =SUMIFS($I:$I,$E:$E,P22) -> 1138648.7 | R22: =VLOOKUP(E22,Sales_Reps!$A$2:$E$100,3,FALSE) -> North | S22: =L22 -> Apparel | T22: =VLOOKUP(D22,Products!$A$2:$F$68,4,FALSE) -> 1173 | V22: R029 | W22: =SUMIF($P$2:$P$2001,V22,$I$2:$I$2001) -> 1016696.8 | X22: =_xlfn.RANK.EQ(W22,$W$2:$W$31,0) -> 5
A23: ORD-00022 | B23: 45354 | C23: CUST-0259 | D23: PROD-036 | E23: R030 | F23: 4 | G23: 3250 | H23: 24.6 | I23: 9802 | J23: Completed | K23: Mumbai | L23: =VLOOKUP(D23,Products!$A$2:$F$61,3,FALSE) -> Home | M23: =VLOOKUP(C23,Customers!$A$2:$F$301,5,FALSE) -> Retail | N23: =VLOOKUP(C23,Customers!$A$2:$F$301,3,FALSE) -> 34 | O23: =VLOOKUP(E23,Sales_Reps!$A$2:$E$31,3,FALSE) -> West | P23: R030 | Q23: =SUMIFS($I:$I,$E:$E,P23) -> 747624.37 | R23: =VLOOKUP(E23,Sales_Reps!$A$2:$E$100,3,FALSE) -> West | S23: =L23 -> Home | T23: =VLOOKUP(D23,Products!$A$2:$F$68,4,FALSE) -> 1556 | V23: R017 | W23: =SUMIF($P$2:$P$2001,V23,$I$2:$I$2001) -> 780384.41 | X23: =_xlfn.RANK.EQ(W23,$W$2:$W$31,0) -> 25
A24: ORD-00023 | B24: 45530 | C24: CUST-0107 | D24: PROD-015 | E24: R030 | F24: 9 | G24: 2720 | H24: 26.2 | I24: 18066.24 | J24: Completed | K24: Pune | L24: =VLOOKUP(D24,Products!$A$2:$F$61,3,FALSE) -> Apparel | M24: =VLOOKUP(C24,Customers!$A$2:$F$301,5,FALSE) -> Retail | N24: =VLOOKUP(C24,Customers!$A$2:$F$301,3,FALSE) -> 50 | O24: =VLOOKUP(E24,Sales_Reps!$A$2:$E$31,3,FALSE) -> West | P24: R030 | Q24: =SUMIFS($I:$I,$E:$E,P24) -> 747624.37 | R24: =VLOOKUP(E24,Sales_Reps!$A$2:$E$100,3,FALSE) -> West | S24: =L24 -> Apparel | T24: =VLOOKUP(D24,Products!$A$2:$F$68,4,FALSE) -> 1962 | V24: R013 | W24: =SUMIF($P$2:$P$2001,V24,$I$2:$I$2001) -> 811524.38 | X24: =_xlfn.RANK.EQ(W24,$W$2:$W$31,0) -> 22
A25: ORD-00024 | B25: 45472 | C25: CUST-0101 | D25: PROD-044 | E25: R003 | F25: 2 | G25: 1650 | H25: 9.4 | I25: 2989.8 | J25: Completed | K25: Hyderabad | L25: =VLOOKUP(D25,Products!$A$2:$F$61,3,FALSE) -> Beauty | M25: =VLOOKUP(C25,Customers!$A$2:$F$301,5,FALSE) -> SMB | N25: =VLOOKUP(C25,Customers!$A$2:$F$301,3,FALSE) -> 40 | O25: =VLOOKUP(E25,Sales_Reps!$A$2:$E$31,3,FALSE) -> North | P25: R003 | Q25: =SUMIFS($I:$I,$E:$E,P25) -> 986692.91 | R25: =VLOOKUP(E25,Sales_Reps!$A$2:$E$100,3,FALSE) -> North | S25: =L25 -> Beauty | T25: =VLOOKUP(D25,Products!$A$2:$F$68,4,FALSE) -> 1222 | V25: R011 | W25: =SUMIF($P$2:$P$2001,V25,$I$2:$I$2001) -> 735207.76 | X25: =_xlfn.RANK.EQ(W25,$W$2:$W$31,0) -> 28
A26: ORD-00025 | B26: 45394 | C26: CUST-0142 | D26: PROD-043 | E26: R023 | F26: 6 | G26: 3350 | H26: 6.1 | I26: 18873.9 | J26: Pending | K26: Chennai | L26: =VLOOKUP(D26,Products!$A$2:$F$61,3,FALSE) -> Beauty | M26: =VLOOKUP(C26,Customers!$A$2:$F$301,5,FALSE) -> Corporate | N26: =VLOOKUP(C26,Customers!$A$2:$F$301,3,FALSE) -> 55 | O26: =VLOOKUP(E26,Sales_Reps!$A$2:$E$31,3,FALSE) -> East | P26: R023 | Q26: =SUMIFS($I:$I,$E:$E,P26) -> 983787.48 | R26: =VLOOKUP(E26,Sales_Reps!$A$2:$E$100,3,FALSE) -> East | S26: =L26 -> Beauty | T26: =VLOOKUP(D26,Products!$A$2:$F$68,4,FALSE) -> 1728 | V26: R022 | W26: =SUMIF($P$2:$P$2001,V26,$I$2:$I$2001) -> 1069570.5 | X26: =_xlfn.RANK.EQ(W26,$W$2:$W$31,0) -> 4
A27: ORD-00026 | B27: 45570 | C27: CUST-0250 | D27: PROD-054 | E27: R019 | F27: 2 | G27: 1010 | H27: 16.5 | I27: 1686.7 | J27: Cancelled | K27: Delhi | L27: =VLOOKUP(D27,Products!$A$2:$F$61,3,FALSE) -> Sports | M27: =VLOOKUP(C27,Customers!$A$2:$F$301,5,FALSE) -> Retail | N27: =VLOOKUP(C27,Customers!$A$2:$F$301,3,FALSE) -> 31 | O27: =VLOOKUP(E27,Sales_Reps!$A$2:$E$31,3,FALSE) -> East | P27: R019 | Q27: =SUMIFS($I:$I,$E:$E,P27) -> 971183.52 | R27: =VLOOKUP(E27,Sales_Reps!$A$2:$E$100,3,FALSE) -> East | S27: =L27 -> Sports | T27: =VLOOKUP(D27,Products!$A$2:$F$68,4,FALSE) -> 516 | V27: R002 | W27: =SUMIF($P$2:$P$2001,V27,$I$2:$I$2001) -> 980063.66 | X27: =_xlfn.RANK.EQ(W27,$W$2:$W$31,0) -> 9
A28: ORD-00027 | B28: 45401 | C28: CUST-0098 | D28: PROD-046 | E28: R006 | F28: 5 | G28: 4880 | H28: 23.6 | I28: 18641.6 | J28: Completed | K28: Delhi | L28: =VLOOKUP(D28,Products!$A$2:$F$61,3,FALSE) -> Beauty | M28: =VLOOKUP(C28,Customers!$A$2:$F$301,5,FALSE) -> Retail | N28: =VLOOKUP(C28,Customers!$A$2:$F$301,3,FALSE) -> 52 | O28: =VLOOKUP(E28,Sales_Reps!$A$2:$E$31,3,FALSE) -> North | P28: R006 | Q28: =SUMIFS($I:$I,$E:$E,P28) -> 1138648.7 | R28: =VLOOKUP(E28,Sales_Reps!$A$2:$E$100,3,FALSE) -> North | S28: =L28 -> Beauty | T28: =VLOOKUP(D28,Products!$A$2:$F$68,4,FALSE) -> 2768 | V28: R018 | W28: =SUMIF($P$2:$P$2001,V28,$I$2:$I$2001) -> 1112289.6 | X28: =_xlfn.RANK.EQ(W28,$W$2:$W$31,0) -> 2
... A31: ORD-00030 | B31: 45367 | C31: CUST-0006 | D31: PROD-055 | E31: R005 | F31: 3 | G31: 2860 | H31: 25.8 | I31: 6366.36 | J31: Completed | K31: Pune | L31: =VLOOKUP(D31,Products!$A$2:$F$61,3,FALSE) -> Sports | M31: =VLOOKUP(C31,Customers!$A$2:$F$301,5,FALSE) -> SMB | N31: =VLOOKUP(C31,Customers!$A$2:$F$301,3,FALSE) -> 44 | O31: =VLOOKUP(E31,Sales_Reps!$A$2:$E$31,3,FALSE) -> North | P31: R005 | Q31: =SUMIFS($I:$I,$E:$E,P31) -> 782445.33 | R31: =VLOOKUP(E31,Sales_Reps!$A$2:$E$100,3,FALSE) -> North | S31: =L31 -> Sports | T31: =VLOOKUP(D31,Products!$A$2:$F$68,4,FALSE) -> 2028 | V31: R016 | W31: =SUMIF($P$2:$P$2001,V31,$I$2:$I$2001) -> 814563.71 | X31: =_xlfn.RANK.EQ(W31,$W$2:$W$31,0) -> 21
A32: ORD-00031 | B32: 45569 | C32: CUST-0241 | D32: PROD-030 | E32: R006 | F32: 7 | G32: 970 | H32: 29.8 | I32: 4766.58 | J32: Completed | K32: Pune | L32: =VLOOKUP(D32,Products!$A$2:$F$61,3,FALSE) -> Grocery | M32: =VLOOKUP(C32,Customers!$A$2:$F$301,5,FALSE) -> Corporate | N32: =VLOOKUP(C32,Customers!$A$2:$F$301,3,FALSE) -> 47 | O32: =VLOOKUP(E32,Sales_Reps!$A$2:$E$31,3,FALSE) -> North | P32: R006 | Q32: =SUMIFS($I:$I,$E:$E,P32) -> 1138648.7 | R32: =VLOOKUP(E32,Sales_Reps!$A$2:$E$100,3,FALSE) -> North | S32: =L32 -> Grocery | T32: =VLOOKUP(D32,Products!$A$2:$F$68,4,FALSE) -> 434
A33: ORD-00032 | B33: 45641 | C33: CUST-0035 | D33: PROD-021 | E33: R026 | F33: 4 | G33: 2760 | H33: 5.9 | I33: 10388.64 | J33: Completed | K33: Hyderabad | L33: =VLOOKUP(D33,Products!$A$2:$F$61,3,FALSE) -> Grocery | M33: =VLOOKUP(C33,Customers!$A$2:$F$301,5,FALSE) -> Retail | N33: =VLOOKUP(C33,Customers!$A$2:$F$301,3,FALSE) -> 53 | O33: =VLOOKUP(E33,Sales_Reps!$A$2:$E$31,3,FALSE) -> West | P33: R026 | Q33: =SUMIFS($I:$I,$E:$E,P33) -> 576305.08 | R33: =VLOOKUP(E33,Sales_Reps!$A$2:$E$100,3,FALSE) -> West | S33: =L33 -> Grocery | T33: =VLOOKUP(D33,Products!$A$2:$F$68,4,FALSE) -> 1435
A34: ORD-00033 | B34: 45343 | C34: CUST-0273 | D34: PROD-037 | E34: R009 | F34: 10 | G34: 660 | H34: 18.3 | I34: 5392.2 | J34: Pending | K34: Hyderabad | L34: =VLOOKUP(D34,Products!$A$2:$F$61,3,FALSE) -> Home | M34: =VLOOKUP(C34,Customers!$A$2:$F$301,5,FALSE) -> Corporate | N34: =VLOOKUP(C34,Customers!$A$2:$F$301,3,FALSE) -> 32 | O34: =VLOOKUP(E34,Sales_Reps!$A$2:$E$31,3,FALSE) -> South | P34: R009 | Q34: =SUMIFS($I:$I,$E:$E,P34) -> 914554.72 | R34: =VLOOKUP(E34,Sales_Reps!$A$2:$E$100,3,FALSE) -> South | S34: =L34 -> Home | T34: =VLOOKUP(D34,Products!$A$2:$F$68,4,FALSE) -> 329 | V34: product_id | W34: West Revenue | X34: Rank
A35: ORD-00034 | B35: 45576 | C35: CUST-0064 | D35: PROD-036 | E35: R019 | F35: 1 | G35: 3250 | H35: 10.7 | I35: 2902.25 | J35: Completed | K35: Hyderabad | L35: =VLOOKUP(D35,Products!$A$2:$F$61,3,FALSE) -> Home | M35: =VLOOKUP(C35,Customers!$A$2:$F$301,5,FALSE) -> SMB | N35: =VLOOKUP(C35,Customers!$A$2:$F$301,3,FALSE) -> 40 | O35: =VLOOKUP(E35,Sales_Reps!$A$2:$E$31,3,FALSE) -> East | P35: R019 | Q35: =SUMIFS($I:$I,$E:$E,P35) -> 971183.52 | R35: =VLOOKUP(E35,Sales_Reps!$A$2:$E$100,3,FALSE) -> East | S35: =L35 -> Home | T35: =VLOOKUP(D35,Products!$A$2:$F$68,4,FALSE) -> 1556 | V35: PROD-001 | W35: =SUMIFS($I$2:$I$2001,$D$2:$D$2001,V35,$R$2:$R$2001,"West") -> 155358.84 | X35: =_xlfn.RANK.EQ(W35,$W$35:$W$94,0) -> 10
A36: ORD-00035 | B36: 45462 | C36: CUST-0118 | D36: PROD-048 | E36: R019 | F36: 8 | G36: 5100 | H36: 26.4 | I36: 30028.8 | J36: Cancelled | K36: Hyderabad | L36: =VLOOKUP(D36,Products!$A$2:$F$61,3,FALSE) -> Beauty | M36: =VLOOKUP(C36,Customers!$A$2:$F$301,5,FALSE) -> Retail | N36: =VLOOKUP(C36,Customers!$A$2:$F$301,3,FALSE) -> 26 | O36: =VLOOKUP(E36,Sales_Reps!$A$2:$E$31,3,FALSE) -> East | P36: R019 | Q36: =SUMIFS($I:$I,$E:$E,P36) -> 971183.52 | R36: =VLOOKUP(E36,Sales_Reps!$A$2:$E$100,3,FALSE) -> East | S36: =L36 -> Beauty | T36: =VLOOKUP(D36,Products!$A$2:$F$68,4,FALSE) -> 2237 | V36: PROD-002 | W36: =SUMIFS($I$2:$I$2001,$D$2:$D$2001,V36,$R$2:$R$2001,"West") -> 105284.4 | X36: =_xlfn.RANK.EQ(W36,$W$35:$W$94,0) -> 23
A37: ORD-00036 | B37: 45442 | C37: CUST-0013 | D37: PROD-040 | E37: R021 | F37: 1 | G37: 1080 | H37: 5.1 | I37: 1024.92 | J37: Completed | K37: Delhi | L37: =VLOOKUP(D37,Products!$A$2:$F$61,3,FALSE) -> Home | M37: =VLOOKUP(C37,Customers!$A$2:$F$301,5,FALSE) -> Retail | N37: =VLOOKUP(C37,Customers!$A$2:$F$301,3,FALSE) -> 41 | O37: =VLOOKUP(E37,Sales_Reps!$A$2:$E$31,3,FALSE) -> East | P37: R021 | Q37: =SUMIFS($I:$I,$E:$E,P37) -> 761507.17 | R37: =VLOOKUP(E37,Sales_Reps!$A$2:$E$100,3,FALSE) -> East | S37: =L37 -> Home | T37: =VLOOKUP(D37,Products!$A$2:$F$68,4,FALSE) -> 519 | V37: PROD-003 | W37: =SUMIFS($I$2:$I$2001,$D$2:$D$2001,V37,$R$2:$R$2001,"West") -> 248025.75 | X37: =_xlfn.RANK.EQ(W37,$W$35:$W$94,0) -> 2 | Z37: =VLOOKUP("PROD-003",Products!$A:$B,2,FALSE) -> Smart Watch
A38: ORD-00037 | B38: 45646 | C38: CUST-0177 | D38: PROD-038 | E38: R009 | F38: 2 | G38: 5490 | H38: 21.1 | I38: 8663.22 | J38: Cancelled | K38: Mumbai | L38: =VLOOKUP(D38,Products!$A$2:$F$61,3,FALSE) -> Home | M38: =VLOOKUP(C38,Customers!$A$2:$F$301,5,FALSE) -> SMB | N38: =VLOOKUP(C38,Customers!$A$2:$F$301,3,FALSE) -> 36 | O38: =VLOOKUP(E38,Sales_Reps!$A$2:$E$31,3,FALSE) -> South | P38: R009 | Q38: =SUMIFS($I:$I,$E:$E,P38) -> 914554.72 | R38: =VLOOKUP(E38,Sales_Reps!$A$2:$E$100,3,FALSE) -> South | S38: =L38 -> Home | T38: =VLOOKUP(D38,Products!$A$2:$F$68,4,FALSE) -> 2549 | V38: PROD-004 | W38: =SUMIFS($I$2:$I$2001,$D$2:$D$2001,V38,$R$2:$R$2001,"West") -> 198124.65 | X38: =_xlfn.RANK.EQ(W38,$W$35:$W$94,0) -> 5
A39: ORD-00038 | B39: 45478 | C39: CUST-0186 | D39: PROD-060 | E39: R001 | F39: 7 | G39: 190 | H39: 28.7 | I39: 948.29 | J39: Completed | K39: Bengaluru | L39: =VLOOKUP(D39,Products!$A$2:$F$61,3,FALSE) -> Sports | M39: =VLOOKUP(C39,Customers!$A$2:$F$301,5,FALSE) -> Retail | N39: =VLOOKUP(C39,Customers!$A$2:$F$301,3,FALSE) -> 42 | O39: =VLOOKUP(E39,Sales_Reps!$A$2:$E$31,3,FALSE) -> North | P39: R001 | Q39: =SUMIFS($I:$I,$E:$E,P39) -> 789849.6 | R39: =VLOOKUP(E39,Sales_Reps!$A$2:$E$100,3,FALSE) -> North | S39: =L39 -> Sports | T39: =VLOOKUP(D39,Products!$A$2:$F$68,4,FALSE) -> 147 | V39: PROD-005 | W39: =SUMIFS($I$2:$I$2001,$D$2:$D$2001,V39,$R$2:$R$2001,"West") -> 7449.9 | X39: =_xlfn.RANK.EQ(W39,$W$35:$W$94,0) -> 60
A40: ORD-00039 | B40: 45355 | C40: CUST-0069 | D40: PROD-058 | E40: R015 | F40: 6 | G40: 2400 | H40: 2.7 | I40: 14011.2 | J40: Completed | K40: Chennai | L40: =VLOOKUP(D40,Products!$A$2:$F$61,3,FALSE) -> Sports | M40: =VLOOKUP(C40,Customers!$A$2:$F$301,5,FALSE) -> Retail | N40: =VLOOKUP(C40,Customers!$A$2:$F$301,3,FALSE) -> 51 | O40: =VLOOKUP(E40,Sales_Reps!$A$2:$E$31,3,FALSE) -> South | P40: R015 | Q40: =SUMIFS($I:$I,$E:$E,P40) -> 1091740.2 | R40: =VLOOKUP(E40,Sales_Reps!$A$2:$E$100,3,FALSE) -> South | S40: =L40 -> Sports | T40: =VLOOKUP(D40,Products!$A$2:$F$68,4,FALSE) -> 974 | V40: PROD-006 | W40: =SUMIFS($I$2:$I$2001,$D$2:$D$2001,V40,$R$2:$R$2001,"West") -> 100869.76 | X40: =_xlfn.RANK.EQ(W40,$W$35:$W$94,0) -> 28
A41: ORD-00040 | B41: 45599 | C41: CUST-0283 | D41: PROD-044 | E41: R023 | F41: 9 | G41: 1650 | H41: 11.6 | I41: 13127.4 | J41: Completed | K41: Delhi | L41: =VLOOKUP(D41,Products!$A$2:$F$61,3,FALSE) -> Beauty | M41: =VLOOKUP(C41,Customers!$A$2:$F$301,5,FALSE) -> SMB | N41: =VLOOKUP(C41,Customers!$A$2:$F$301,3,FALSE) -> 50 | O41: =VLOOKUP(E41,Sales_Reps!$A$2:$E$31,3,FALSE) -> East | P41: R023 | Q41: =SUMIFS($I:$I,$E:$E,P41) -> 983787.48 | R41: =VLOOKUP(E41,Sales_Reps!$A$2:$E$100,3,FALSE) -> East | S41: =L41 -> Beauty | T41: =VLOOKUP(D41,Products!$A$2:$F$68,4,FALSE) -> 1222 | V41: PROD-007 | W41: =SUMIFS($I$2:$I$2001,$D$2:$D$2001,V41,$R$2:$R$2001,"West") -> 38531.35 | X41: =_xlfn.RANK.EQ(W41,$W$35:$W$94,0) -> 48
A42: ORD-00041 | B42: 45606 | C42: CUST-9507 | D42: PROD-038 | E42: R006 | F42: 4 | G42: 5490 | H42: 12.8 | I42: 19149.12 | J42: Cancelled | K42: Chennai | L42: =VLOOKUP(D42,Products!$A$2:$F$61,3,FALSE) -> Home | M42: =VLOOKUP(C42,Customers!$A$2:$F$301,5,FALSE) -> #N/A | N42: =VLOOKUP(C42,Customers!$A$2:$F$301,3,FALSE) -> #N/A | O42: =VLOOKUP(E42,Sales_Reps!$A$2:$E$31,3,FALSE) -> North | P42: R006 | Q42: =SUMIFS($I:$I,$E:$E,P42) -> 1138648.7 | R42: =VLOOKUP(E42,Sales_Reps!$A$2:$E$100,3,FALSE) -> North | S42: =L42 -> Home | T42: =VLOOKUP(D42,Products!$A$2:$F$68,4,FALSE) -> 2549 | V42: PROD-008 | W42: =SUMIFS($I$2:$I$2001,$D$2:$D$2001,V42,$R$2:$R$2001,"West") -> 7807.1 | X42: =_xlfn.RANK.EQ(W42,$W$35:$W$94,0) -> 59
...

Sheet Customers
A1: customer_id | B1: customer_name | C1: age | D1: city | E1: segment | F1: signup_date
A2: CUST-0001 | B2: Amit Agarwal | C2: 36 | D2: Pune | E2: Retail | F2: 44819
A3: CUST-0002 | B3: Vihaan Malhotra | C3: 42 | D3: Pune | E3: Corporate | F3: 44984
A4: CUST-0003 | B4: Navya Malhotra | C4: 33 | D4: Mumbai | E4: Retail | F4: 44059
A5: CUST-0004 | B5: Aaradhya Mehta | C5: 53 | D5: delhi | E5: Retail | F5: 44054
A6: CUST-0005 | B6: Myra Malhotra | C6: 52 | D6: Chennai | E6: Corporate | F6: 45037
A7: CUST-0006 | B7: Shaurya Iyer | C7: 44 | D7: Pune | E7: SMB | F7: 44302
A8: CUST-0007 | B8: Dhruv Joshi | C8: 47 | D8: Bengaluru | E8: Retail | F8: 44498
A9: CUST-0008 | B9: Kavita Malhotra | C9: 39 | D9: Pune | E9: SMB | F9: 45162
A10: CUST-0009 | B10: Neha Malhotra | C10: 61 | D10: Mumbai | E10: Retail | F10: 44343
A11: CUST-0010 | B11: Aaradhya Gupta | C11: 61 | D11: Mumbai | E11: SMB | F11: 44975
A12: CUST-0011 | B12: Diya Menon | C12: 41 | D12: Chennai | E12: Corporate | F12: 44821
A13: CUST-0012 | B13: Prisha Desai | C13: 43 | D13: Pune | E13: Retail | F13: 44718
... A301: CUST-0300 | B301: Rohit Nair | C301: 38 | D301: Mumbai | E301: Retail | F301: 43932

Sheet Products
A1: product_id | B1: product_name | C1: category | D1: unit_cost | E1: unit_price | F1: is_active
A2: PROD-001 | B2: Smartphone Pro | C2: Electronics | D2: 2405 | E2: 5330 | F2: TRUE
A3: PROD-002 | B3: Wireless Earbuds | C3: Electronics | D3: 1052 | E3: 2600 | F3: TRUE
A4: PROD-003 | B4: Smart Watch | C4: Electronics | D4: 1665 | E4: 3570 | F4: TRUE
A5: PROD-004 | B5: Laptop Bag | C5: Electronics | D5: 1559 | E5: 3870 | F5: TRUE
A6: PROD-005 | B6: Power Bank | C6: Electronics | D6: 128 | E6: 300 | F6: TRUE
A7: PROD-006 | B7: Bluetooth Speaker | C7: Electronics | D7: 2865 | E7: 3970 | F7: TRUE
A8: PROD-007 | B8: USB-C Cable | C8: Electronics | D8: 861 | E8: 1430 | F8: TRUE
A9: PROD-008 | B9: Wireless Mouse | C9: Electronics | D9: 1259 | E9: 2660 | F9: FALSE
A10: PROD-009 | B10: Mechanical Keyboard | C10: Electronics | D10: 517 | E10: 1220 | F10: TRUE
A11: PROD-010 | B11: Tablet Stand | C11: Electronics | D11: 1149 | E11: 2640 | F11: TRUE
A12: PROD-011 | B12: Cotton T-Shirt | C12: Apparel | D12: 1748 | E12: 3450 | F12: TRUE
A13: PROD-012 | B13: Denim Jeans | C13: Apparel | D13: 1886 | E13: 3160 | F13: TRUE
... A61: PROD-060 | B61: Gym Gloves | C61: Sports | D61: 147 | E61: 190 | F61: TRUE

Sheet Sales_Reps
A1: rep_id | B1: rep_name | C1: region | D1: hire_date | E1: team_lead_id
A2: R001 | B2: Rajesh Malhotra | C2: North | D2: 44207 | V2: =UNIQUE(P2:P2001) -> #NAME? | W2: =SUMIF($P$2:$P$2001,V2,$I$2:$I$2001) -> 0 | X2: =_xlfn.RANK.EQ(W2,$W$2:$W$2001,0) -> 1
A3: R002 | B3: Sunita Malhotra | C3: North | D3: 44028
A4: R003 | B4: Amit Singh | C4: North | D4: 43651
A5: R004 | B5: Priya Singh | C5: North | D5: 44907
A6: R005 | B6: Vikram Patel | C6: North | D6: 43588 | E6: R001
A7: R006 | B7: Neha Desai | C7: North | D7: 44131 | E7: R001
A8: R007 | B8: Suresh Menon | C8: North | D8: 43493 | E8: R001
A9: R008 | B9: Kavita Patel | C9: North | D9: 44693 | E9: R001
A10: R009 | B10: Manoj Patel | C10: South | D10: 44804 | E10: R002
A11: R010 | B11: Divya Rao | C11: South | D11: 43904 | E11: R002
A12: R011 | B12: Anil Verma | C12: South | D12: 44622 | E12: R002
A13: R012 | B13: Pooja Nair | C13: South | D13: 44890 | E13: R002
A14: R013 | B14: Sanjay Kapoor | C14: South | D14: 45215 | E14: R002
A15: R014 | B15: Ritu Menon | C15: South | D15: 44469 | E15: R002
A16: R015 | B16: Deepak Shah | C16: South | D16: 45231 | E16: R002
A17: R016 | B17: Anjali Chopra | C17: South | D17: 43614 | E17: R002
... A31: R030 | B31: Kiran Bhatt | C31: West | D31: 44506 | E31: R004

Sheet Sheet3

Sheet Targets
A1: rep_id | B1: Jan-24 | C1: Feb-24 | D1: Mar-24 | E1: Apr-24 | F1: May-24 | G1: Jun-24 | H1: Jul-24 | I1: Aug-24 | J1: Sep-24 | K1: Oct-24 | L1: Nov-24 | M1: Dec-24
A2: R001 | B2: 231324 | C2: 171682 | D2: 234376 | E2: 326967 | F2: 350588 | G2: 385324 | H2: 307980 | I2: 327947 | J2: 181016 | K2: 374039 | L2: 212805 | M2: 405999
A3: R002 | B3: 438126 | C3: 346266 | D3: 329993 | E3: 370744 | F3: 294660 | G3: 341556 | H3: 151934 | I3: 223794 | J3: 438641 | K3: 344308 | L3: 296172 | M3: 304288
A4: R003 | B4: 358703 | C4: 320519 | D4: 327321 | E4: 298753 | F4: 254636 | G4: 351929 | H4: 264723 | I4: 216459 | J4: 391945 | K4: 362426 | L4: 289199 | M4: 301863 | O4: =VLOOKUP("R015",Targets!$A$2:$M$100,12,FALSE) -> 418857
A5: R004 | B5: 389594 | C5: 376422 | D5: 324156 | E5: 420255 | F5: 409107 | G5: 269954 | H5: 179097 | I5: 370568 | J5: 387395 | K5: 243454 | L5: 232530 | M5: 201999
A6: R005 | B6: 436862 | C6: 391158 | D6: 340224 | E6: 170548 | F6: 229390 | G6: 349525 | H6: 154683 | I6: 320848 | J6: 354452 | K6: 377180 | L6: 342347 | M6: 183362
A7: R006 | B7: 348734 | C7: 358191 | D7: 250385 | E7: 219657 | F7: 249365 | G7: 435704 | H7: 260892 | I7: 250741 | J7: 358402 | K7: 379858 | L7: 213280 | M7: 224634
A8: R007 | B8: 280057 | C8: 330342 | D8: 336856 | E8: 227425 | F8: 233647 | G8: 307088 | H8: 370724 | I8: 440008 | J8: 406347 | K8: 217357 | L8: 299289 | M8: 214568
A9: R008 | B9: 252886 | C9: 206057 | D9: 318209 | E9: 411230 | F9: 448660 | G9: 171135 | H9: 305339 | I9: 432264 | J9: 294273 | K9: 371409 | L9: 284207 | M9: 437068
A10: R009 | B10: 268752 | C10: 393256 | D10: 310649 | E10: 246237 | F10: 271287 | G10: 314545 | H10: 406506 | I10: 334930 | J10: 348625 | K10: 408928 | L10: 243749 | M10: 418409
A11: R010 | B11: 384734 | C11: 156698 | D11: 283679 | E11: 276085 | F11: 409270 | G11: 285230 | H11: 304233 | I11: 178221 | J11: 284216 | K11: 287373 | L11: 229082 | M11: 298969
A12: R011 | B12: 186029 | C12: 151419 | D12: 253251 | E12: 379757 | F12: 204209 | G12: 179396 | H12: 378008 | I12: 182649 | J12: 267772 | K12: 350352 | L12: 358042 | M12: 359960
A13: R012 | B13: 352158 | C13: 251181 | D13: 321255 | E13: 300863 | F13: 241731 | G13: 393275 | H13: 313561 | I13: 283604 | J13: 429065 | K13: 194420 | L13: 254168 | M13: 389283
A14: R013 | B14: 350003 | C14: 384951 | D14: 424777 | E14: 323282 | F14: 427290 | G14: 363819 | H14: 279496 | I14: 190932 | J14: 347420 | K14: 160215 | L14: 388600 | M14: 437901
A15: R014 | B15: 307327 | C15: 377256 | D15: 236349 | E15: 321223 | F15: 268119 | G15: 294020 | H15: 312180 | I15: 390845 | J15: 432317 | K15: 277613 | L15: 373411 | M15: 214349
A16: R015 | B16: 414207 | C16: 376391 | D16: 192739 | E16: 165892 | F16: 187659 | G16: 283837 | H16: 434871 | I16: 369518 | J16: 171986 | K16: 328460 | L16: 418857 | M16: 159947
... A31: R030 | B31: 151584 | C31: 221679 | D31: 385157 | E31: 290386 | F31: 236041 | G31: 407985 | H31: 184446 | I31: 342894 | J31: 180344 | K31: 292917 | L31: 314858 | M31: 364057

Sheet Q1_Lookups
A1: Q1 - LOOKUP FUNCTIONS (25 marks total)
A2: VLOOKUP · INDEX-MATCH · Two-way lookup · Chain lookup · Approximate lookup · Self-join
A4: Q# | B4: Question | C4: Marks | D4: Hint | E4: Your Answer | F4: Format
A5: Q1.1 | B5: For order ORD-00234, what is the customer_id? | C5: 3 | D5: Simple VLOOKUP on Orders sheet. | E5: =VLOOKUP("ORD-00234",Orders!A2:K2001,3,FALSE) -> CUST-0173 | F5: CUST-####
A6: Q1.2 | B6: For order ORD-00456, what is the product_name? (You will need to look up the product_id first, then find its name in Products.) | C6: 3 | D6: Two-step lookup, or nested VLOOKUP. | E6: =VLOOKUP(VLOOKUP("ORD-00456",Orders!A2:K2001,4,FALSE),Products!A2:F61,2,FALSE) -> Dumbbells 5kg | F6: Text
A7: Q1.3 | B7: For order ORD-00987, what is the rep_name of the sales rep? Note: the rep_name is in a column that appears to the LEFT of what you might look up first. | C7: 3 | D7: VLOOKUP has directional limits - INDEX/MATCH does not. | E7: =INDEX(Sales_Reps!B2:B31,MATCH(VLOOKUP("ORD-00987",Orders!A2:K2001,5,FALSE),Sales_Reps!A2:A31,0)) -> Nisha Menon | F7: Text
A8: Q1.4 | B8: From the Targets sheet, what is the target value for rep R012 in the month Mar-24? | C8: 4 | D8: Two-way lookup: row = rep_id, column = month. | E8: =INDEX(Targets!B2:M31,MATCH("R012",Targets!A2:A31,0),MATCH("Mar-24",Targets!B1:M1,0)) -> 321255 | F8: Whole number
A9: Q1.5 | B9: For order ORD-01500, what is the CATEGORY of the product ordered? (Chain: order → product_id → category) | C9: 4 | D9: Multi-hop lookup across sheets. | E9: =VLOOKUP(VLOOKUP("ORD-01500",Orders!A2:K2001,4,FALSE),Products!A2:F61,3,FALSE) -> Electronics | F9: Text
A10: Q1.6 | B10: For order ORD-00789, which DISCOUNT SLAB does it fall in? Use the slab table below (rows 20-24). Slab breakpoints are the LOWER bound of each range. | C10: 3 | D10: Approximate-match VLOOKUP (sort ascending, TRUE / omit last arg). | E10: =VLOOKUP(VLOOKUP("ORD-00789",Orders!A2:K2001,8,FALSE),B17:C20,2,TRUE) -> Bronze | F10: Text
A11: Q1.7 | B11: For order ORD-01234, in one cell produce the string: "<rep_name> (<sales_region>)" - e.g. "Amit Singh (South)". | C11: 3 | D11: Two lookups joined with & or CONCATENATE. | E11: =INDEX(Sales_Reps!B2:B31,MATCH(VLOOKUP("ORD-01234",Orders!A2:K2001,5,FALSE),Sales_Reps!A2:A31,0))&" ("&INDEX(Sales_Reps!C2:C31,MATCH(VLOOKUP("ORD-01234",Orders!A2:K2001,5,FALSE),Sales_Reps!A2:A31,0))&")" -> Sanjay Kapoor (South) | F11: Text
A12: Q1.8 | B12: What is the rep_name of the TEAM LEAD for rep R017? (The Sales_Reps sheet has team_lead_id - you need to self-join to find that person's name.) | C12: 2 | D12: Look up the team_lead_id, then look up THAT id's rep_name. | E12: =INDEX(Sales_Reps!B2:B31,MATCH(INDEX(Sales_Reps!E2:E31,MATCH("R017",Sales_Reps!A2:A31,0)),Sales_Reps!A2:A31,0)) -> Amit Singh | F12: Text
B15: DISCOUNT SLAB REFERENCE TABLE (use for Q1.6)
B17: Discount % (Lower) | C17: Slab
B18: 0 | C18: Bronze
B19: 5 | C19: Silver
B20: 15 | C20: Gold
B21: 25 | C21: Platinum

Sheet Q2_Cleaning
A1: Q2 - DATA CLEANING & QUALITY DIAGNOSTICS (20 marks total)
A2: Duplicates · Whitespace · Case Inconsistency · Referential Integrity · Discontinued SKUs · Anomaly Patterns
A4: Q# | B4: Question | C4: Marks | D4: Hint | E4: Your Answer | F4: Format
A5: Q2.1 | B5: How many DUPLICATE rows exist in the Orders sheet (i.e., how many order_id values appear more than once)? Count each duplicate as ONE (not the extras). | C5: 3 | D5: COUNTIF > 1, then count. Watch what you're counting - rows or IDs. | E5: =SUMPRODUCT((Orders!A2:A2001<>"")*(COUNTIF(Orders!A2:A2001,Orders!A2:A2001)>1)/COUNTIF(Orders!A2:A2001,Orders!A2:A2001)) -> 20 | F5: Whole number
A6: Q2.2 | B6: How many customers in the Customers sheet have LEADING or TRAILING whitespace in their customer_name? | C6: 3 | D6: Compare LEN vs LEN(TRIM). Or use SUMPRODUCT with a boolean. | E6: =SUMPRODUCT(--(LEN(Customers!B2:B301)<>LEN(TRIM(Customers!B2:B301)))) -> 15 | F6: Whole number
A7: Q2.3 | B7: The Customers sheet has some cities in inconsistent case (e.g., "mumbai", "MUMBAI", "Mumbai"). How many DISTINCT cities exist AFTER standardizing case? | C7: 3 | D7: Combine PROPER/UPPER with a de-dup count. SUMPRODUCT + 1/COUNTIF trick works. | E7: =COUNTA(UNIQUE(UPPER(TRIM(Customers!D2:D301)))) -> 1 | F7: Whole number
A8: Q2.4 | B8: How many orders reference a customer_id that DOES NOT EXIST in the Customers sheet? (Broken foreign key) | C8: 4 | D8: Use MATCH with ISNA/ISERROR, then count. | E8: =SUMPRODUCT(--ISNA(MATCH(Orders!C2:C2001,Customers!A2:A301,0))) -> 30 | F8: Whole number
A9: Q2.5 | B9: How many orders reference a product that is currently DISCONTINUED (is_active = FALSE in the Products sheet)? | C9: 3 | D9: VLOOKUP the is_active flag, then count where FALSE. | E9: =SUMPRODUCT(--(IFERROR(VLOOKUP(Orders!D2:D2001,Products!A2:F61,6,FALSE),TRUE)=FALSE)) -> 0 | F9: Whole number
A10: Q2.6 | B10: Find the "suspicious pattern": how many orders have payment_status = "Cancelled" AND a discount_pct > 20%? (This pattern often indicates promo abuse - a real-world diagnostic query.) | C10: 4 | D10: COUNTIFS with two criteria. | E10: =COUNTIFS(Orders!J2:J2001,"Cancelled",Orders!H2:H2001,">20%") -> 238 | F10: Whole number

Sheet Q3_Aggregation
A1: Q3 - CONDITIONAL AGGREGATION (25 marks total)
A2: SUMIFS · COUNTIFS · AVERAGEIFS · Nested IF logic · Multi-sheet aggregation · Top-N logic
A4: Q# | B4: Question | C4: Marks | D4: Hint | E4: Your Answer | F4: Format
A5: Q3.1 | B5: What is the TOTAL REVENUE (sum of final_amount) for orders in Q3 2024 (Jul-Sep) where ship_city is Mumbai? | C5: 4 | D5: SUMIFS with 3 conditions: date >= start, date <= end, city = Mumbai. Beware case issues. | E5: =SUMPRODUCT((Orders!A2:A2001<>"")*(Orders!B2:B2001>=DATE(2024,7,1))*(Orders!B2:B2001<=DATE(2024,9,30))*(UPPER(TRIM(Orders!K2:K2001))="MUMBAI")*Orders!I2:I2001) -> 1217239 | F5: Currency
A6: Q3.2 | B6: How many orders have discount_pct > 15% AND payment_status = "Completed"? | C6: 3 | D6: COUNTIFS with two conditions. | E6: =COUNTIFS(Orders!H2:H2001,">15%",Orders!J2:J2001,"Completed") -> 1432 | F6: Whole number
A7: Q3.3 | B7: What is the AVERAGE final_amount for orders where the product CATEGORY is "Electronics" AND the customer SEGMENT is "Corporate"? Note: Both fields come from OTHER sheets - you'll need helper columns. | C7: 5 | D7: Helper columns in Orders: VLOOKUP category from Products, VLOOKUP segment from Customers. Then AVERAGEIFS. | E7: 13981.4 | F7: Currency
A8: Q3.4 | B8: What is the COMBINED REVENUE of the TOP 3 reps by total revenue? (Sum of the 3 highest rep totals.) | C8: 4 | D8: Compute per-rep totals, then use SUMPRODUCT with LARGE, or sort and sum top 3. | E8: 3415946 | F8: Currency
A9: Q3.5 | B9: For rep R015 in Nov-24: compute the actual revenue and compare to the target (from Targets sheet). Report the PERFORMANCE TIER using: <80% → "Below", 80-120% → "On Track", >120% → "Exceeds". Return only the tier text. | C9: 5 | D9: Nested IF (or IFS): compute actual/target ratio, then classify. | E9: Below | F9: Text
A10: Q3.6 | B10: What is the TOTAL revenue from Corporate segment customers aged between 30 and 40 (both inclusive)? | C10: 4 | D10: Helper columns for age and segment. Then SUMIFS with numeric range. | E10: 982568.4 | F10: Currency | N10: 982568.4

Sheet Q4_Pivot
A1: Q4 - PIVOT TABLES (20 marks total)
A2: 2D Pivots · Filters · % of Row Total · Date Grouping · Calculated Fields · Cross-Sheet Data
A4: Q# | B4: Question | C4: Marks | D4: Hint | E4: Your Answer | F4: Format
A5: Q4.1 | B5: Build a pivot with sales_region as rows and product category as columns, values = SUM of final_amount. What value appears at the intersection of "South" and "Electronics"? | C5: 4 | D5: You need to add category (from Products) and region (from Sales_Reps) as columns to Orders first. Insert PivotTable from combined data. | E5: 1314107 | F5: Currency
A6: Q4.2 | B6: Build a pivot: rows = order month (Jan-24 through Dec-24), columns = sales_rep_id, values = SUM of final_amount. What is the HIGHEST single value in the entire pivot? (One number.) | C6: 4 | D6: After building, use MAX() over the pivot data range, or scan visually. | E6: 1138649 | F6: Currency
A7: Q4.3 | B7: For the North sales_region only: what PERCENTAGE of total revenue comes from the Apparel category? Configure the pivot with Show Values As → % of Row Total. | C7: 4 | D7: Pivot: rows=region, cols=category, values=sum(final_amount), Show Values As = % of Row Total. | E7: 0.1402 | F7: Percentage
A8: Q4.4 | B8: Group order dates by QUARTER in a pivot. What is the total revenue for Q4 2024 (Oct-Dec)? | C8: 4 | D8: PivotTable → Group By → Quarter. Or SUMIFS with date range. | E8: 6459443 | F8: Currency
A9: Q4.5 | B9: Create a CALCULATED FIELD in the pivot: profit_margin = (unit_price - unit_cost) / unit_price. What is the AVERAGE profit_margin for orders shipped to Delhi? Give as a percentage. | C9: 4 | D9: Add unit_cost via VLOOKUP as helper column. Create pivot calculated field, filter to Delhi. | E9: 0.5159 | F9: Percentage

Sheet Q5_Advanced
A1: Q5 - ADVANCED (10 marks total)
A2: RANK · Running Totals · TEXTJOIN · LARGE + INDEX/MATCH · Multi-condition top-N
A4: Q# | B4: Question | C4: Marks | D4: Hint | E4: Your Answer | F4: Format
A5: Q5.1 | B5: Rank all sales reps by total revenue (highest = rank 1). Who (name) is at RANK #7? | C5: 2 | D5: Per-rep totals, then use RANK.EQ, or sort. Return the rep_name at position 7. | E5: Amit Singh | F5: Text
A6: Q5.2 | B6: What is the CUMULATIVE revenue from Jan 2024 through the end of Aug 2024? (Sum of final_amount where order_date <= 31-Aug-2024.) | C6: 2 | D6: SUMIFS with date <=. | E6: 18050690 | F6: Currency
A7: Q5.3 | B7: Among orders where the sales rep is in the WEST region: which product (by name) has the 2nd highest total revenue? | C7: 3 | D7: Helper: sales_region on orders. Filter/pivot to West, sum by product, rank, get #2, VLOOKUP product name. | E7: =VLOOKUP("PROD-003",Products!$A:$B,2,FALSE) -> Smart Watch | F7: Text
A8: Q5.4 | B8: Concatenate the names of the top 5 reps by revenue into a single cell, separated by " | " (space-pipe-space). | C8: 2 | D8: TEXTJOIN with delimiter " | ". Combine with LARGE to pull top 5. | F8: Text
A9: Q5.5 | B9: What is the HIGHEST single order value (final_amount) where ship_city = "Bengaluru" AND the product's category = "Grocery"? | C9: 1 | D9: MAXIFS with a category helper column, or nested MAX(IF()). | F9: Currency
E12: 18050690
